Traceback (most recent call last):
  File "/home/runner/miniconda3/envs/cookbook-dev/lib/python3.10/site-packages/jupyter_core/utils/__init__.py", line 154, in wrapped
    asyncio.get_running_loop()
RuntimeError: no running event loop

During handling of the above exception, another exception occurred:

Traceback (most recent call last):
  File "/home/runner/miniconda3/envs/cookbook-dev/lib/python3.10/site-packages/jupyter_cache/executors/utils.py", line 58, in single_nb_execution
    executenb(
  File "/home/runner/miniconda3/envs/cookbook-dev/lib/python3.10/site-packages/nbclient/client.py", line 1319, in execute
    return NotebookClient(nb=nb, resources=resources, km=km, **kwargs).execute()
  File "/home/runner/miniconda3/envs/cookbook-dev/lib/python3.10/site-packages/jupyter_core/utils/__init__.py", line 158, in wrapped
    return loop.run_until_complete(inner)
  File "/home/runner/miniconda3/envs/cookbook-dev/lib/python3.10/asyncio/base_events.py", line 649, in run_until_complete
    return future.result()
  File "/home/runner/miniconda3/envs/cookbook-dev/lib/python3.10/site-packages/nbclient/client.py", line 709, in async_execute
    await self.async_execute_cell(
  File "/home/runner/miniconda3/envs/cookbook-dev/lib/python3.10/site-packages/nbclient/client.py", line 1062, in async_execute_cell
    await self._check_raise_for_error(cell, cell_index, exec_reply)
  File "/home/runner/miniconda3/envs/cookbook-dev/lib/python3.10/site-packages/nbclient/client.py", line 918, in _check_raise_for_error
    raise CellExecutionError.from_cell_and_msg(cell, exec_reply_content)
nbclient.exceptions.CellExecutionError: An error occurred while executing the following cell:
------------------
basin_mask = merged_mask(basins, ds[['lat', 'lon']])
------------------


[0;31m---------------------------------------------------------------------------[0m
[0;31mTypeError[0m                                 Traceback (most recent call last)
Cell [0;32mIn[11], line 1[0m
[0;32m----> 1[0m basin_mask [38;5;241m=[39m [43mmerged_mask[49m[43m([49m[43mbasins[49m[43m,[49m[43m [49m[43mds[49m[43m[[49m[43m[[49m[38;5;124;43m'[39;49m[38;5;124;43mlat[39;49m[38;5;124;43m'[39;49m[43m,[49m[43m [49m[38;5;124;43m'[39;49m[38;5;124;43mlon[39;49m[38;5;124;43m'[39;49m[43m][49m[43m][49m[43m)[49m

File [0;32m~/miniconda3/envs/cookbook-dev/lib/python3.10/site-packages/xmip/regionmask.py:188[0m, in [0;36mmerged_mask[0;34m(basins, ds, lon_name, lat_name, merge_dict, verbose)[0m
[1;32m    137[0m [38;5;28;01mdef[39;00m[38;5;250m [39m[38;5;21mmerged_mask[39m(
[1;32m    138[0m     basins, ds, lon_name[38;5;241m=[39m[38;5;124m"[39m[38;5;124mlon[39m[38;5;124m"[39m, lat_name[38;5;241m=[39m[38;5;124m"[39m[38;5;124mlat[39m[38;5;124m"[39m, merge_dict[38;5;241m=[39m[38;5;28;01mNone[39;00m, verbose[38;5;241m=[39m[38;5;28;01mFalse[39;00m
[1;32m    139[0m ):
[1;32m    140[0m [38;5;250m    [39m[38;5;124;03m"""Combine geographical basins (from regionmask) to larger ocean basins.[39;00m
[1;32m    141[0m 
[1;32m    142[0m [38;5;124;03m    Parameters[39;00m
[0;32m   (...)[0m
[1;32m    186[0m 
[1;32m    187[0m [38;5;124;03m    """[39;00m
[0;32m--> 188[0m     mask [38;5;241m=[39m [43mbasins[49m[38;5;241;43m.[39;49m[43mmask[49m[43m([49m[43mds[49m[43m,[49m[43m [49m[43mlon_name[49m[38;5;241;43m=[39;49m[43mlon_name[49m[43m,[49m[43m [49m[43mlat_name[49m[38;5;241;43m=[39;49m[43mlat_name[49m[43m)[49m
[1;32m    190[0m     [38;5;28;01mif[39;00m merge_dict [38;5;129;01mis[39;00m [38;5;28;01mNone[39;00m:
[1;32m    191[0m         merge_dict [38;5;241m=[39m _default_merge_dict()

[0;31mTypeError[0m: Regions.mask() got an unexpected keyword argument 'lon_name'

